Workbook

Sheet Rekap
A2: Rupiah | H2: Dollar USD
A3: Tanggal | B3: Nama | C3: Kode Area | D3: Uang Masuk | E3: Uang Keluar | F3: Saldo | H3: Nama | I3: Kode Area | J3: Uang Masuk | K3: Uang Keluar | L3: Saldo
B4: Uang Marmer | C4: K9 | D4: 153140000 | E4: 0 | F4: =D4-E4 -> 153140000 | H4: Uang Masuk | J4: 100100 | K4: 0 | L4: =J4-K4 -> 100100
A5: 45746 | B5: DP Marmer | C5: K9 | D5: 0 | E5: 82000000 | F5: =D4-E5 -> 71140000 | H5: DP Alure | I5: K9 | J5: 0 | K5: 70000 | L5: =L4+J5-K5 -> 30100
B6: Bayar UPVC | C6: K9 | D6: 135000000 | E6: 0 | F6: =F5+D6-E6 -> 206140000 | H6: Tukar menjadi Rupiah | J6: 0 | K6: 30100 | L6: =L5+J6-K6 -> 0
B7: DP UPVC Tahap 1 | C7: C21 | D7: 0 | E7: 50000000 | F7: =F6+D7-E7 -> 156140000 | H7: Uang Masuk | J7: 90000 | K7: 0 | L7: =L6+J7-K7 -> 90000
B8: Uang masuk Tukar 30.100 USD | C8: K9 | D8: 487467000 | E8: 0 | F8: =F7+D8-E8 -> 643607000 | H8: Pelunasan Allure | K8: 90000 | L8: =L7+J8-K8 -> 0
B9: Bayar AC Daikin DP 30% | C9: C21 | D9: 0 | E9: 54080000 | F9: =F8+D9-E9 -> 589527000 | L9: =L8+J9-K9 -> 0
B10: Lantai Kamar Utama dan Anak | C10: C21 | D10: 0 | E10: 28039600 | F10: =F9+D10-E10 -> 561487400 | L10: =L9+J10-K10 -> 0
B11: Kramik Kamar Mandi, Garasi, Teras | C11: C21 | D11: 0 | E11: 40453950 | F11: =F10+D11-E11 -> 521033450 | L11: =L10+J11-K11 -> 0
B12: Pembayaran Tahap 2 UPVC | C12: C21 | D12: 0 | E12: 50000000 | F12: =F11+D12-E12 -> 471033450 | L12: =L11+J12-K12 -> 0
B13: Cat Tembok | C13: C21 | D13: 0 | E13: 9743000 | F13: =F12+D13-E13 -> 461290450 | L13: =L12+J13-K13 -> 0
B14: Plamir Tambahan | C14: C21 | D14: 0 | E14: 400000 | F14: =F13+D14-E14 -> 460890450 | L14: =L13+J14-K14 -> 0
B15: Solar Heater | C15: C21 | D15: 0 | E15: 26000000 | F15: =F14+D15-E15 -> 434890450 | L15: =L14+J15-K15 -> 0
B16: Starlink Internet | C16: C21 | D16: 0 | E16: 8145000 | F16: =F15+D16-E16 -> 426745450 | L16: =L15+J16-K16 -> 0
B17: Saklar dan Colokan Snider | C17: C21 | D17: 0 | E17: 3849300 | F17: =F16+D17-E17 -> 422896150 | L17: =L16+J17-K17 -> 0
A18: 45453 | B18: DP Lift Schindler | C18: K9 | D18: 0 | E18: 210900000 | F18: =F17+D18-E18 -> 211996150 | L18: =L17+J18-K18 -> 0
B19: DP Interior Ruang utama | C19: C21 | D19: 0 | E19: 66600000 | F19: =F18+D19-E19 -> 145396150 | L19: =L18+J19-K19 -> 0
B20: Pembayaran Tahap 3 UPVC | C20: C21 | D20: 0 | E20: 10000000 | F20: =F19+D20-E20 -> 135396150 | L20: =L19+J20-K20 -> 0
B21: Handle Pintu Belakang Bardi | C21: C21 | D21: 0 | E21: 2174000 | F21: =F20+D21-E21 -> 133222150 | L21: =L20+J21-K21 -> 0
B22: Ongkos Pasang | C22: C21 | E22: 600000 | F22: =F21+D22-E22 -> 132622150 | L22: =L21+J22-K22 -> 0
B23: Saklar dan Colokan Snider | C23: C21 | D23: 0 | E23: 4503100 | F23: =F22+D23-E23 -> 128119050 | L23: =L22+J23-K23 -> 0
B24: Handle Pintu Utama Bardi | C24: C21 | D24: 0 | E24: 4400000 | F24: =F23+D24-E24 -> 123719050 | L24: =L23+J24-K24 -> 0
B25: Ongkos Pasang | C25: C21 | E25: 400000 | F25: =F24+D25-E25 -> 123319050 | L25: =L24+J25-K25 -> 0
B26: Cat ruang dalam | C26: C21 | D26: 0 | E26: 4426000 | F26: =F25+D26-E26 -> 118893050 | L26: =L25+J26-K26 -> 0
B27: Sink Dapur Bersih | C27: C21 | D27: 0 | E27: 3336500 | F27: =F26+D27-E27 -> 115556550 | L27: =L26-K27 -> 0
B28: Sink Dapur Kotor | C28: C21 | D28: 0 | E28: 2067400 | F28: =F27+D28-E28 -> 113489150 | L28: =L27-K28 -> 0
B29: Lantai Kamar Utama | C29: C21 | D29: 0 | E29: =801400+120000 -> 921400 | F29: =F28+D29-E29 -> 112567750 | L29: =L28-K29 -> 0
B30: DP UPVC Tahap 4 | C30: C21 | D30: 0 | E30: 25000000 | F30: =F29+D30-E30 -> 87567750 | L30: =L29-K30 -> 0
B31: Pembelin silent | C31: C21 | D31: 0 | E31: 405200 | F31: =F30+D31-E31 -> 87162550 | L31: =L30-K31 -> 0
B32: Uang Masuk Rupiah | D32: 280000000 | E32: 0 | F32: =F31+D32-E32 -> 367162550 | L32: =L31-K32 -> 0
B33: Uang Masuk Tukar $ 19.900 | D33: 325365000 | E33: 0 | F33: =F32+D33-E33 -> 692527550 | L33: =L32-K33 -> 0
A34: 45475 | B34: DP infinity Kramik | C34: K9 | D34: 0 | E34: 222781440 | F34: =F33+D34-E34 -> 469746110 | L34: =L33-K34 -> 0
B35: Pembelian Cat Luar | C35: C21 | D35: 0 | E35: 3668000 | F35: =F34+D35-E35 -> 466078110 | L35: =L34-K35 -> 0
B36: Pelunasan AC | C36: C21 | D36: 0 | E36: 87370000 | F36: =F35+D36-E36 -> 378708110 | L36: =L35-K36 -> 0
B37: Pembayaran Interior tahap 2 | C37: C21 | D37: 0 | E37: 61500000 | F37: =F36+D37-E37 -> 317208110 | L37: =L36-K37 -> 0
B38: Saklar dan Colokan Snider | C38: C21 | D38: 0 | E38: 1262432 | F38: =F37+D38-E38 -> 315945678 | L38: =L37-K38 -> 0
B39: Shower Box Semua kamar mandi | C39: C21 | D39: 0 | E39: 23265000 | F39: =F38+D39-E39 -> 292680678 | L39: =L38-K39 -> 0
B40: Penambahan Interior | C40: C21 | D40: 0 | E40: 2002000 | F40: =F39+D40-E40 -> 290678678 | L40: =L39-K40 -> 0
B41: Pembelian Keran Sink Pantry | C41: C21 | D41: 0 | E41: 703250 | F41: =F40+D41-E41 -> 289975428 | L41: =L40-K41 -> 0
...

Sheet K9
B2: Pekerjaan | C2: Brand | D2: Penawaran | F2: Pembayaran 1 | G2: Pembayaran 2 | H2: Pembayaran 3 | I2: Pembayaran 4 | J2: Pembayaran 5 | K2: Pembayaran 6 | L2: Pembayaran 7 | M2: Pembayaran 8 | N2: Sisa | O2: Total Sudah Dibayar
D3: USD | E3: Rupiah
B4: Kusen dan Pintu Utama | C4: Allure | D4: 167182 | F4: 70000 | G4: 13591 | N4: =D4-F4-G4 -> 83591 | P4: =N4*16500 -> 1379251500
B5: Interior Design K9 | C5: Sarita | E5: =94800000+71100000-23700000 -> 142200000 | F5: =Rekap!E64 -> 94800000 | G5: =Rekap!E190 -> 47400000 | N5: =E5-F5-G5-H5 -> 0
B6: Arsitek Design K9 | C6: Manthra | E6: 115000000 | F6: =Rekap!E84 -> 115000000 | N6: =E6-F6-G6-H6 -> 0
B7: Kusen dan Pintu Pendukung | C7: Astral 1 | E7: 651114046 | F7: =Rekap!E53 -> 325557023 | G7: =Rekap!E216 -> 100000000 | H7: =Rekap!E218 -> 151325688 | N7: =E7-F7-G7-H7-I7-J7-K7-L7-M7 -> 74231335
B8: Disain Taman | C8: Dhona | E8: =18000000+115785000 -> 133785000 | F8: =Rekap!E182 -> 9000000 | G8: =Rekap!E194 -> 7200000 | H8: =Rekap!E367 -> 57892500 | N8: =E8-F8-G8-H8-I8-J8-K8-L8-M8 -> 59692500
B9: Kusen dan Pintu Tambahan | C9: Astral Aplikator | E9: 211377293 | F9: =Rekap!E175 -> 105688647 | N9: =E9-F9-G9-H9-I9-J9-K9-L9-M9 -> 105688646 | P9: =N9 -> 105688646
B10: Kusen dan Pintu Kayu Lantai 1 dan 2 | C10: Asherindo SM | E10: 368000000 | F10: =Rekap!E195 -> 150000000 | G10: =Rekap!E261 -> 120000000 | H10: =Rekap!E350 -> 60000000 | N10: =E10-F10-G10-H10-I10-J10-K10-L10-M10 -> 38000000 | P10: =N10 -> 38000000
B11: Kusen dan Pintu Kayu Lantai 3 | C11: Asherindo SM | E11: 124445313 | F11: =Rekap!E351 -> 60000000 | N11: =E11-F11-G11-H11-I11-J11-K11-L11-M11 -> 64445313 | P11: =N11 -> 64445313
B12: Tambahan Kusen dan Pintu Kayu Lantai 1 dan 2 | C12: Asherindo SM | E12: 25000000 | F12: =Rekap!E255 -> 25000000 | N12: =E12-F12-G12-H12-I12 -> 0
B13: Aksesoris Engsel Pintu | C13: Asherindo SM | E13: 98870000 | F13: =Rekap!E229 -> 47150000 | G13: =Rekap!E249 -> 51720000 | N13: =E13-F13-G13-H13-I13 -> 0
B14: Tambah Aksesoris Engsel Pintu | C14: Asherindo SM | E14: 25600000 | F14: =Rekap!E378 -> 25600000 | N14: =E14-F14-G14-H14-I14 -> 0
B15: Pekerjaan AC | C15: Daikin | E15: =1000000000+150000000 -> 1150000000 | F15: =Rekap!E57 -> 404825000 | G15: =Rekap!E78 -> 250000000 | H15: =Rekap!E88 -> 250000000 | I15: =Rekap!E176 -> 150000000 | N15: =E15-F15-G15-H15-I15-J15-K15-L15-M15 -> 95175000 | P15: =N15 -> 95175000
B16: Pekerjaan Lift | C16: Schindler | E16: =405150000+16650000 -> 421800000 | F16: =Rekap!E18 -> 210900000 | G16: =Rekap!E129 -> 202575000 | N16: =E16-F16-G16-H16-I16-J16-K16-L16-M16 -> 8325000
B17: Pekerjaan Panel Surya | E17: 0 | F17: 0
B18: Plafond Area Lt 1 dan 2 | C18: Mandala Plafond | E18: 835700000 | F18: =Rekap!E71 -> 487750000 | G18: =Rekap!E141 -> 438925000 | H18: =Rekap!E161 -> 250000000 | I18: =Rekap!E263 -> 100000000 | N18: =(E18+E19+E20+E21+E22)-F18:F22-G18:G22-H18:H22-I18:I22-J18-K18-L18-M18 -> 158925000 | P18: =N18 -> 158925000
B19: Plafond Area Lt 3 | C19: Mandala Plafond | E19: 302600000
B20: Plafond Tenda Teras Kolam Renang | C20: Mandala Plafond | E20: 195000000
B21: Plafond Tambahan Revisi | C21: Mandala Plafond | E21: =13800000+6800000 -> 20600000
B22: Plafond Area Service | C22: Mandala Plafond | E22: 81700000
B23: Plafond Attic Room Lantai 3 | C23: Mandala Plafond | E23: =18700000+4600000 -> 23300000 | F23: =Rekap!E197 -> 18640000 | N23: =E23-F23-G23-H23-I23-J23-K23-L23-M23 -> 4660000
B24: Plafond Tambahan Tiang Attic Room | C24: Mandala Plafond | E24: =55100000+13700000 -> 68800000 | F24: =Rekap!E232 -> 30960000 | N24: =E24-F24-G24-H24-I24-J24-K24-L24-M24 -> 37840000
B25: Special Lighting Fasad dan Ruang Tamu | C25: Galaxindo | E25: 221450000 | F25: =Rekap!E79 -> 95000000 | G25: =Rekap!E102 -> 30000000 | H25: =Rekap!E196 -> 57000000 | I25: =Rekap!E188 -> 1450000 | N25: =E25-F25-G25-H25-I25-J25-K25-L25-M25 -> 38000000
B26: Special Lighting General Room | C26: Sena Lighting | E26: 146941250 | F26: =Rekap!E174 -> 73470625 | G26: =Rekap!E395 -> 7340000 | N26: =E26-F26-G26-H26-I26-J26-K26-L26-M26 -> 66130625
B27: Sound System Cilling | C27: Bose Distributor | E27: 160000000 | F27: =Rekap!E105 -> 80000000 | G27: =Rekap!E407 -> 64000000 | N27: =E27-F27-G27-H27-I27-J27-K27-L27-M27 -> 16000000
B28: CCTV | N28: =E28-F28-G28-H28-I28-J28-K28-L28-M28 -> 0
B29: Internet Indihome | E29: 18726000 | F29: =Rekap!E80 -> 2500000 | G29: =Rekap!E100 -> 10302520 | N29: =E29-F29-G29-H29-I29-J29-K29-L29-M29 -> 5923480
B30: Kaca Sky Light Attic Room | E30: 50000000 | F30: =Rekap!E189 -> 15000000 | G30: =Rekap!E368 -> 15170000 | N30: =E30-F30-G30-H30-I30-J30-K30-L30-M30 -> 19830000
B31: Kanopi Besi Koridor Samping Lt 3 | C31: Satria Maju Bersama | E31: 20000000 | F31: =Rekap!E198 -> 5000000 | G31: =Rekap!E224 -> 8000000 | N31: =E31-F31-G31-H31-I31-J31-K31-L31-M31 -> 7000000
B32: Kanopi Kaca Koridor Samping Lt 3 | C32: Goel | E32: 0 | F32: =Rekap!E314 -> 7000000 | G32: =Rekap!E398 -> 8300000 | N32: =E32-F32-G32-H32-I32-J32-K32-L32-M32 -> -15300000
B33: Kanopi Besi Koridor Samping Lt 2 | C33: Dedi Besi | E33: 12750000 | F33: =Rekap!E209 -> 6000000 | N33: =E33-F33-G33-H33-I33-J33-K33-L33-M33 -> 6750000
B34: Railling Tangga Depan | C34: Satria Maju Bersama | E34: 40710000 | F34: =Rekap!E86 -> 15000000 | G34: =Rekap!E135 -> 10000000 | H34: =Rekap!E148 -> 5000000 | I34: =Rekap!E147+ Rekap!E154 -> 6500000 | N34: =E34-F34-G34-H34-I34-J34-K34-L34-M34 -> 4210000
B35: Railling Tangga Belakang | C35: Satria Maju Bersama | E35: 39300000 | F35: =Rekap!E185 -> 10000000 | G35: =Rekap!E191 -> 6000000 | H35: =Rekap!E204 -> 10000000 | I35: =Rekap!E213 -> 7000000 | J35: =Rekap!E239 -> 5000000 | N35: =E35-F35-G35-H35-I35-J35-K35-L35-M35 -> 1300000
B36: Water Heater | C36: Wika WH | E36: 136200000 | F36: =Rekap!E166 -> 68100000 | G36: =Rekap!E330 -> 49032000 | H36: =Rekap!E391 -> 18048000 | N36: =E36-F36-G36-H36-I36-J36-K36-L36-M36 -> 1020000
B37: Pagar Depan | C37: Dedi Besi | E37: 29000000 | F37: =Rekap!E90 -> 15000000 | G37: =Rekap!E400 -> 2000000 | N37: =E37-F37-G37-H37-I37-J37-K37-L37-M37 -> 12000000
B38: Cover Ruang Gym Lantai 2 | C38: Dedi Besi | E38: 85450000 | F38: =Rekap!E243 -> 40000000 | N38: =E38-F38-G38-H38-I38-J38-K38-L38-M38 -> 45450000
B39: Railing Balkon Lantai 3 | C39: Dedi Besi | E39: 50000000 | F39: =Rekap!E305 -> 15000000 | G39: =Rekap!E390 -> 13875000 | N39: =E39-F39-G39-H39-I39-J39-K39-L39-M39 -> 21125000
B40: Kanopi Ruang Utillity | C40: Dedi Besi | E40: 26235000 | F40: =Rekap!E386 -> 26235000
B41: Pengerjaan Batu Aksesoris | C41: Mughni | E41: 4205000 | F41: =Rekap!E353 -> 4205000
...

Sheet K8
B2: Pekerjaan | C2: Brand | D2: Penawaran | F2: Pembayaran 1 | G2: Pembayaran 2 | H2: Pembayaran 3 | I2: Pembayaran 4 | N2: Sisa | O2: Total Sudah Dibayar
D3: USD | E3: Rupiah
B4: Pekerjaan AC Ruangan | C4: Daikin | E4: 63954400 | F4: =Rekap!E228+Rekap!E230 -> 63954400 | N4: =E4-F4-G4-H4 -> 0
B5: Pekerjaan AC Kamar | C5: Gree | E5: 22333075 | F5: =Rekap!E253 -> 16733000 | G5: =Rekap!E298 -> 5600075 | N5: =E5-F5-G5-H5 -> 0
B6: Pekerjaan Cat Ruangan | C6: Tukang | F6: =Rekap!E235 -> 3017000 | N6: =E6-F6-G6-H6 -> -3017000
B7: Perbaikan Lampu | C7: Tukang Shopee | E7: 5577890 | F7: =Rekap!E233+Rekap!E237 -> 2309260 | G7: =Rekap!E269+Rekap!E270+Rekap!E271 -> 2880840 | H7: =Rekap!E281+Rekap!E290 -> 387790 | N7: =E7-F7-G7-H7 -> 0
B8: Perbaikan Interior | C8: rumahgue.id | E8: 35000000 | F8: =Rekap!E240+Rekap!E241 -> 21808000 | G8: =Rekap!E247 -> 6000000 | H8: =Rekap!E266 -> 6730000 | N8: =E8-F8-G8-H8 -> 462000
B9: Pembuatan Pager Kemang | C9: Tukang | E9: 50000000 | F9: =Rekap!E242 -> 8203000 | G9: =Rekap!E250 -> 4935000 | H9: =Rekap!E252 -> 30600000 | I9: =Rekap!E262 -> 1740000 | J9: =Rekap!E273+Rekap!E274 -> 1975000 | K9: =Rekap!E283 -> 6990000 | L9: =Rekap!E304+Rekap!E306+Rekap!E313+Rekap!E318 -> 9705720 | N9: =E9-F9-G9-H9 -> 6262000
B10: Pembelian Pohon | C10: Akmal | E10: 8800000 | F10: =Rekap!E248 -> 5800000 | G10: =Rekap!E258 -> 3000000 | N10: =E10-F10-G10-H10 -> 0
B11: Pembelian Sanitary | C11: Toto | F11: =Rekap!E267+Rekap!E268 -> 3385760 | G11: =Rekap!E272 -> 1027400 | H11: =Rekap!E282 -> 11007826 | I11: =Rekap!E286+Rekap!E287+Rekap!E284 -> 5571784 | J11: =Rekap!E329 -> 256946 | N11: =E11-F11-G11-H11 -> -15420986
B12: Pembelian Keramik | C12: Roman | E12: 10735000 | F12: =Rekap!E294 -> 10735000 | N12: =E12-F12-G12-H12 -> 0
B13: Pekerjaan Paving depan | C13: Sentracon | E13: 15000000 | F13: =Rekap!E292 -> 8000000 | G13: =Rekap!E296+Rekap!E297 -> 2497500 | H13: =Rekap!E302+Rekap!E307+Rekap!E320+Rekap!E323+Rekap!E328 -> 3875000 | I13: =Rekap!E308+Rekap!E315+Rekap!E327+Rekap!E334 -> 10000000 | J13: =Rekap!E309 -> 7000000 | K13: =Rekap!E311+Rekap!E316 -> 3625000 | N13: =E13-F13-G13-H13 -> 627500
B14: Pekerjaan Perapihan Taman | C14: PPSU | E14: 3000000 | F14: =Rekap!E293 -> 3000000 | G14: =Rekap!E295 -> 2000000 | N14: =E14-F14-G14-H14 -> -2000000
B15: Pembelian Batu dan Pasang | C15: Mughni | E15: 20100000 | F15: =Rekap!E289 -> 6100000 | G15: =Rekap!E322 -> 1950000 | H15: =Rekap!E342+Rekap!E343 -> 20755000 | I15: =Rekap!E341 -> 14070000 | J15: =Rekap!E348+Rekap!E349+Rekap!E354+Rekap!E359+Rekap!E362 -> 8913000 | N15: =E15-F15-G15-H15 -> -8705000
B16: Pemasangan Kayu | F16: =Rekap!E357+Rekap!E358 -> 3195575 | N16: =E16-F16-G16-H16 -> -3195575
B17: Gaji Tukang | F17: =Rekap!E361 -> 6200000
B18: Pemasangan Batu Tabur Pendopo | C18: Kadir | F18: =Rekap!E363 -> 5500000
B19: Pembuatan Jembatan | C19: Dedi | E19: 105000000 | F19: =Rekap!E331 -> 75000000 | G19: =Rekap!E345 -> 15000000 | H19: =Rekap!E360 -> 10000000 | N19: =E19-F19-G19-H19 -> 5000000
B20: Pembuatan Pager Tanaman | C20: Dedi | E20: 11400000
B21: Pembuatan Fasad | C21: Soni | E21: 350000000 | F21: =Rekap!E333 -> 150000000 | G21: =Rekap!E337 -> 100000000 | N21: =E21-F21-G21-H21 -> 100000000
B22: Bahan Pasang Listrik dan Lampu | C22: Iwan | F22: =Rekap!E365 -> 1900000
B24: Pembelian TV | C24: Hartono Mall | F24: =Rekap!E340 -> 23100000
N25: =E25-F25-G25-H25 -> 0
N26: =E26-F26-G26-H26 -> 0
B27: Pembayaran Listrik Januari | F27: =Rekap!E276 -> 1892537 | N27: =E27-F27-G27-H27 -> -1892537
B28: Pembayaran Listrik Februari | F28: =Rekap!E338 -> 2729719 | N28: =E28-F28-G28-H28-I28 -> -2729719
E31: =SUM(E7:E29) -> 614612890 | F31: =SUM(F4:F29) -> 422563251 | G31: =SUM(G4:G29) -> 144890815 | H31: =SUM(H4:H29) -> 83355616 | I31: =SUM(I4:I29) -> 31381784 | J31: =SUM(J4:J29) -> 18144946 | K31: =SUM(K4:K29) -> 10615000 | L31: =SUM(L4:L29) -> 9705720 | N31: =SUM(N7:N29) -> 78407683 | O31: =F31+G31+H31+I31+J31+K31+L31 -> 720657132

Sheet C21
B2: Pekerjaan | C2: Brand | D2: Penawaran | F2: Pembayaran 1 | G2: Pembayaran 2 | H2: Pembayaran 3 | I2: Pembayaran 4 | N2: Sisa | O2: Total Sudah Dibayar
D3: USD | E3: Rupiah
B4: Pekerjaan AC Ruangan | C4: Daikin | N4: =E4-F4-G4-H4 -> 0
B5: Pekerjaan AC Kamar | C5: Gree | N5: =E5-F5-G5-H5 -> 0
B6: Pekerjaan Cat Ruangan | C6: Tukang | N6: =E6-F6-G6-H6 -> 0
B7: Perbaikan Lampu | C7: Tukang Shopee | N7: =E7-F7-G7-H7 -> 0
B8: Perbaikan Interior | C8: rumahgue.id | N8: =E8-F8-G8-H8 -> 0
B9: Pembuatan Pager Kemang | C9: Tukang | N9: =E9-F9-G9-H9 -> 0
B10: Pembelian Pohon | C10: Akmal | N10: =E10-F10-G10-H10 -> 0
B11: Pembelian Sanitary | C11: Toto | N11: =E11-F11-G11-H11 -> 0
B12: Pembelian Keramik | C12: Roman | N12: =E12-F12-G12-H12 -> 0
B13: Pekerjaan Paving depan | C13: Sentracon | N13: =E13-F13-G13-H13 -> 0
B14: Pekerjaan Perapihan Taman | C14: PPSU | N14: =E14-F14-G14-H14 -> 0
B15: Pembelian Batu dan Pasang | C15: Mughni | N15: =E15-F15-G15-H15 -> 0
B16: Pemasangan Kayu | N16: =E16-F16-G16-H16 -> 0
B17: Gaji Tukang
B18: Pemasangan Batu Tabur Pendopo | C18: Kadir
B19: Pembuatan Jembatan | C19: Dedi | N19: =E19-F19-G19-H19 -> 0
B20: Pembuatan Pager Tanaman | C20: Dedi
B21: Pembuatan Fasad | C21: Soni | N21: =E21-F21-G21-H21 -> 0
B22: Bahan Pasang Listrik dan Lampu | C22: Iwan
B24: Pembelian TV | C24: Hartono Mall
N25: =E25-F25-G25-H25 -> 0
N26: =E26-F26-G26-H26 -> 0
B27: Pembayaran Listrik Januari | N27: =E27-F27-G27-H27 -> 0
B28: Pembayaran Listrik Februari | N28: =E28-F28-G28-H28-I28 -> 0
E31: =SUM(E7:E29) -> 0 | F31: =SUM(F4:F29) -> 0 | G31: =SUM(G4:G29) -> 0 | H31: =SUM(H4:H29) -> 0 | I31: =SUM(I4:I29) -> 0 | J31: =SUM(J4:J29) -> 0 | K31: =SUM(K4:K29) -> 0 | L31: =SUM(L4:L29) -> 0 | N31: =SUM(N7:N29) -> 0 | O31: =F31+G31+H31+I31+J31+K31+L31 -> 0

Sheet Kebutuhan
A1: Nama Ruangan | B1: Lantai | C1: Progress | D1: Kekurangan | E1: Tipe Barang
A2: Powder Room Ruang Tamu | B2: Lantai 1 | D2: Westafle
D3: Keran Westafle
D4: Kabinet
D5: Airpurefire
D6: Kloset | E6: Kohler
A7: Kamar Mandi Tamu | B7: Lantai 1 | D7: Westafle
D8: Keran Westafle
D9: Kaca Shower
D10: Shower | E10: Toto
D11: Kloset | E11: Kohler
A12: Kamar Mandi Office | B12: Lantai 1 | D12: Westafle
D13: Keran Westafle
D14: Kaca Shower
D15: Shower | E15: Toto
D16: Kloset | E16: Toto
A17: Kamar Mandi Eyang | B17: Lantai 2 | D17: Westafle
D18: Keran Westafle
D19: Kabinet
D20: Kaca Shower
D21: Shower
D22: Kloset
A23: Powder Room Ungu | B23: Lantai 2 | D23: Westafle
D24: Keran Westafle
D25: Kabinet
D26: Airpurefire
D27: Kloset
A28: Kamar Mandi Fira | B28: Lantai 3 | D28: Westafle
D29: Keran Westafle
D30: Kabinet
D31: Kaca Shower
D32: Shower
D33: Kloset
A34: Kamar Mandi Rara | B34: Lantai 3 | D34: Westafle
D35: Keran Westafle
D36: Kabinet
D37: Kaca Shower
D38: Shower
D39: Kloset
A40: Kamar Mandi Zahra | B40: Lantai 3 | D40: Westafle
...
